Workbook
Name dest_copy: commodities[Name]
Name liquid: Notes!$G$3:$G$5
Name processor: _xlfn.ANCHORARRAY(Notes!$M$3)
Name raw_material_producer: commodities[Name]
Name raw_material_producer: commodities[Name]
Name raw_material_producer: commodities[Name]
Name raw_material_producer: commodities[Name]
Name rmp_copy: commodities[Name]
Name Slicer_Airport_Code: #N/A
Name Slicer_City: #N/A
Name Slicer_City1: #N/A
Name Slicer_Commodity1: #N/A
Name Slicer_Conversion_Process1: #N/A
Name Slicer_FAA_Hub_Size: #N/A
Name Slicer_Nth_Pioneer1: #N/A
Name Slicer_Resource1: #N/A
Name Slicer_Scenario1: #N/A
Name Slicer_State: #N/A
Name Slicer_State1: #N/A
Name Slicer_State2: #N/A
Name Slicer_State3: #N/A
Name Slicer_Terminal_Name: #N/A
Name solid: Notes!$F$3:$F$6
Name solidliquid: Notes!$H$3:$H$9
Name ultimate_destination: commodities[Name]
Name ultimate_destination: commodities[Name]
Name ultimate_destination: commodities[Name]
Name ultimate_destination: commodities[Name]

Sheet Instructions
A1: Freight and Fuel Transportation Optimization Tool (FTOT) Sustainable Aviation Fuel (SAF) Scenario Setup Template [BETA Version]
A2: The Freight and Fuel Transportation Optimization Tool (FTOT) is a flexible scenario-testing tool that optimizes the transportation of materials for future energy and freight scenarios. FTOT was developed at the U.S. Department of Transportation’s Volpe National Transportation Systems Center.
A3: The FTOT Sustainable Aviation Fuel (SAF) Scenario Setup Template is a user-friendly helper tool to assist FTOT users in setting up new SAF supply chain scenarios. The specific supply chain modeled includes the movement of user-selected feedstock from county-level raw material producers to refineries, which produce SAF. SAF then flows to blending facilities, which create a fuel blend that flows to airports as the ultimate destination.
A5: Each copy of this template should be updated to reflect input data for a single scenario. When complete, the template can be used as input to the "Scenario Setup Conversion" tool in the FTOT Tools suite, which in turn will output a new scenario directory with (1) the facility-commodity CSV files representing the scenario's supply chain, (2) the scenario XML file with all scenario settings, and (3) the batch file needed to execute the FTOT program.
A6: Note: The template is currently designed for simple supply chains and does not create optional input files needed for certain more advanced scenarios such as disruption scenarios or scenarios with facility production schedules. The supplementary CSV files for those advanced scenarios should be created outside of this template. Refer to the FTOT documentation and quick start/reference scenarios for more guidance.
A8: Instructions for the FTOT SAF Scenario Setup Template
A10: 1. Create a copy of this template file. Give it a descriptive filename.
A12: 2. Start on the "SAF Filters" tab. This tab will be used to query the template's associated datasets to built the scenario.
A13: a) Use the filters and textboxes to provide feedstock information. Select a feedstock market scenario (single select), the feedstock-producing states in your scenario (multiselect), a commodity type (single select), and specific resources within that commodity type to include (multiselect). In addition, enter a decimal value (0 to 1) for the share of available feedstock that is available for use in the SAF supply chain, and enter a maximum transport distance for the feedstock.
A14: b) Use the filters and textboxes to provide refinery information. Select a processing technology (single select) and plant type (single select) for use by FTOT's refinery candidate generation functionality. Also indicate if the scenario should include existing refineries, and if yes, from which states (multiselect).
A15: c) Use the filters and textboxes to provide blender information. Multiselect from the listed states, cities, and terminal names to narrow down the list of blenders. Also enter a SAF blend ratio (0 to 1).
A16: d) Use the filters to provide airport information. Multiselect from the listed states, cities, FAA hub sizes, and airport codes to narrow down the list of airports.
... A57: FTOT-Public GitHub Repository

Sheet SAF Filters
B2: STEP 1. Use filters and text boxes to provide FEEDSTOCK information.
B3: Note: Filters (c) and (d) are impacted by filters in Step 2. Clear filters in both Step 1 and Step 2 to reset.
B4: a) Select market scenario* | F4: b) Select states | J4: c) Select commodity | N4: d) Select specific resources | S4: e) Enter usable share of feedstock
B5: Single select | F5: Ctrl + click to multiselect | J5: Single select | N5: Ctrl + click to multiselect
S6: Share of available feedstock to be used for SAF.
S7: Enter a decimal value between 0 and 1, inclusive.
S9: 1
S13: f) Enter maximum transport distance
S15: Max transport distance for feedstock in default distance units.
B16: *See Table ES-1 in the 2023 Billion-Ton Report for scenario definitions: | S16: Please specify default distance units on the Configuration tab.
B17: DOE BETO 2023 Billion-Ton Report | S17: 500
T18: =IF(ISERROR(_xlfn.NUMBERVALUE(S17)), "Error: Enter a number value","")
B19: {=IF(COUNTA(_xlfn.UNIQUE(_xlfn._xlws.FILTER(SAF_Scenario[Scenario], _xlfn.TOCOL(SAF_Scenario[Filtered])=1)))<>1,"Error: Select 1 item only","")}
S20: Next: Move to Step 2.
J24: {=IF(COUNTA(_xlfn.UNIQUE(_xlfn._xlws.FILTER(SAF_Cand_Refinery[Commodity], _xlfn.TOCOL(SAF_Cand_Refinery[Filtered])=1)))<>1,"Error: Select 1 item only","")} | N24: =IF(AND(Notes!AA2="Ethanol",Notes!CJ30=0),"Error: Selected states in (b) have zero ethanol biorefineries","")
B27: STEP 2. Use filters and text boxes to provide REFINERY information
B28: Note: Filters (a) and (b) are impacted by feedstock selections above. Clear filters in both Step 1 and Step 2 to reset.
B30: a) Select processing technology | F30: b) Select plant type | J30: c) Include existing SAF refineries? | Q30: d) If Y, select states to query for existing refineries
B31: Single select | F31: Single select | Q31: Ctrl + click to multiselect. Selections will be ignored if step (c) is "N"
J32: If Y, a list of current and planned refineries will be queried.
J33: Note that refineries may not exist for the selected commodity
J34: and conversion process.
J35: Regardless, FTOT will also propose locations for new refineries.
J37: Y | T37: Next: Move to Step 3.
F38: {=IF(COUNTA(_xlfn.UNIQUE(_xlfn._xlws.FILTER(SAF_Cand_Refinery[Nth/Pioneer], _xlfn.TOCOL(SAF_Cand_Refinery[Filtered])=1)))<>1,"Error: Select 1 item only","")}
B40: {=IF(COUNTA(_xlfn.UNIQUE(_xlfn._xlws.FILTER(SAF_Cand_Refinery[Conversion Process], _xlfn.TOCOL(SAF_Cand_Refinery[Filtered])=1)))<>1,"Error: Select 1 item only","")}
B45: STEP 3. Use filters and text boxes to provide BLENDER information
B47: a) Select blenders by filtering by state, city, and/or terminal name. | M47: b) Review selected blending facilities. | T47: c) Enter SAF blend ratio
B48: Ctrl + click to multiselect
M49: Review the remaining "Terminal Name" values to the left. | T49: Share of SAF to use in the fuel blend.
M50: These blending facilities will be available in your scenario. | T50: Enter a decimal between 0 and 1, inclusive.
M51: Adjust filters to refine selections if needed.
M52: Note that too many blenders may increase runtime. | T52: 0.5
M54: ="Number of blenders selected: " & SUBTOTAL(3,SAF_Blender[Terminal Name]) -> Number of blenders selected: 44
T56: Next: Move to Step 4.
B67: STEP 4. Use filters to select AIRPORTS.
B68: Note: Only airports with available demand information are included. Please reach out to the FTOT team if you would like other airports to be added.
B69: a) Select airports by filtering by state, city, airport code, and/or FAA hub size. | P69: b) Review selected airports.
B70: Ctrl + click to multiselect
P72: Review the remaining "Airport Code" values in to the left.
...

Sheet Configuration
A1: Instructions
A2: 1) Under Basic Information, provide the required information in all cells with grey fill. When available, use the drop-down menus to select a value.
A3: 2) Review the fields in the Additional Settings section. The cells with grey fill are populated with default values but can be changed by the user. Modify these values as needed for your scenario, using the drop-down menus when provided.
A5: Basic Information
A7: Scenario Settings | B7: Provide text:
A8: Scenario Name | B8: HEFA scenario from FOG in PNW
A9: Scenario Description | B9: HEFA supply chain in Pacific Northwest with existing refineries
A11: Default Units | B11: Select from drop-down menu:
A12: Commodity Amounts (Solids) | B12: tons
A13: Commodity Amounts (Liquids) | B13: thousand gallons
A14: Distance | B14: miles
A15: Currency | B15: usd
A17: File Paths | B17: Enter full file paths or "None":
A18: RMP GIS Feature Layer | B18: None | C18: Leave as None for SAF scenario template
A19: Processor GIS Feature Layer | B19: None | C19: Leave as None for SAF scenario template
A20: Destination GIS Feature Layer | B20: None | C20: Leave as None for SAF scenario template
A22: Permitted Modes | B22: Set TRUE or FALSE:
A23: Road | B23: TRUE
A24: Rail | B24: TRUE
A25: Water | B25: TRUE
A26: Pipeline Crude | B26: FALSE | C26: Does not apply to SAF scenario template. Leave as False.
A27: Pipeline Product | B27: TRUE | C27: Set to TRUE to allow SAF blend to flow on pipeline.
A29: Additional Settings
A31: Additional File Paths | B31: Enter full file paths or "None":
A32: Common Data Folder | B32: C:\FTOT\scenarios\common_data | C32: Should be the location of the downloaded FTOT common_data folder.
A33: Network GDB | B33: C:\FTOT\scenarios\common_data\networks\FTOT_Public_US_Contiguous_Network_v2026.gdb
A34: Impedance Weights CSV | B34: C:\FTOT\scenarios\common_data\networks\default_impedance_weights.csv | C34: Set to "None" if not applicable.
A35: Commodities CSV | B35: None | C35: Leave as None for SAF scenario template
A36: Disruption CSV | B36: None | C36: Set to "None" if not applicable.
A37: Schedules CSV | B37: None | C37: Set to "None" if not applicable.
A38: Detailed Emissions CSV | B38: None | C38: Set to "None" if not applicable.
A39: Speed Time CSV | B39: None | C39: Set to "None" if not applicable.
A41: Transport Costs | B41: Enter numbers: | C41: Enter units:
A42: Truck Base Cost | B42: 0.27 | C42: usd/ton/mi | D42: Should be in default currency units per unit of commodity mass and distance (e.g., usd/ton/mi).
A43: Railroad Base Cost | B43: 0.052 | C43: usd/ton/mi | D43: Should be in default currency units per unit of commodity mass and distance (e.g., usd/ton/mi).
A44: Barge Base Cost | B44: 0.038 | C44: usd/ton/mi | D44: Should be in default currency units per unit of commodity mass and distance (e.g., usd/ton/mi).
A45: Artificial Link Base Cost | B45: 0.27 | C45: usd/ton/mi | D45: Should be in default currency units per unit of mass and distance (e.g., usd/ton/mi).
A46: Transloading Cost | B46: 13.91 | C46: usd/ton | D46: Should be in default currency units per unit of mass (e.g., usd/ton).
A48: Vehicle Characteristics | B48: Set TRUE / FALSE toggle and enter numbers: | C48: Select units from drop-down and/or enter units:
A49: Truck Load (Solids) | B49: 26 | C49: tons
...

Sheet Commodities and Processes
A1: For Review Only
A2: DO NOT EDIT. This worksheet auto-populates based on selections in the SAF Filters tab. The commodities and processes on this sheet are presented for user reference only.
A3: If needed, you can customize this information in the CSV files created after running the Scenario Setup Tool.
C4: {=IF(ISERROR(_xlfn._xlws.FILTER(Notes!O:O,(Notes!Q:Q="N")*(Notes!S:S=0))),"","ERROR! Enter a max transport distance for: "&_xlfn.CONCAT(_xlfn.UNIQUE(_xlfn._xlws.FILTER(Notes!O:O,(Notes!Q:Q="N")*(Notes!S:S=0)))&" "))}
A5: Commodities | E5: Processes
C6: Required for use w/ non-existing facilities | E6: Process name: | F6: =Notes!AH3 -> makeSAF
A7: Name | B7: Phase | C7: Max Transport Distance | E7: Existing facilities: | F7: =Notes!AH4 -> N | K7: Do not edit -->
A8: =Notes!AC4 -> SAF | B8: =Notes!AD4 -> liquid | E8: Inputs | F8: Input Amount | G8: Input Units | H8: Outputs | I8: Output Amount | J8: Output Units | K8: Process Name | L8: Existing Facilities
A9: =Notes!AC5 -> fuel_blend | B9: =Notes!AD5 -> liquid | E9: =Notes!AG6 -> FOG | F9: =Notes!AH6 -> 1 | G9: =Notes!AI6 -> tons | H9: =Notes!AJ6 -> SAF | I9: =Notes!AK6 -> 127.21129 | J9: =Notes!AL6 -> gallon | K9: =F6 -> makeSAF | L9: =F7 -> N
A10: =Notes!AC6 -> FOG | B10: =Notes!AD6 -> solid | C10: =Notes!AE6 -> 500
E11: Process name: | F11: =Notes!AH8 -> blendSAF
E12: Existing facilities: | F12: =Notes!AH9 -> Y | K12: Do not edit -->
E13: Inputs | F13: Input Amount | G13: Input Units | H13: Outputs | I13: Output Amount | J13: Output Units | K13: Process Name | L13: Existing Facilities
E14: =Notes!AG11 -> SAF | F14: =Notes!AH11 -> 1 | G14: =Notes!AI11 -> gallons | H14: =Notes!AJ11 -> fuel_blend | I14: =Notes!AK11 -> 2 | J14: =Notes!AL11 -> gallons | K14: =F11 -> blendSAF | L14: =F12 -> Y
E16: Process name: | F16: =IF('SAF Filters'!$J$37="Y",Notes!AH13,"") -> makeSAF_Existing
E17: Existing facilities: | F17: =IF('SAF Filters'!$J$37="Y",Notes!AH14,"") -> Y | K17: Do not edit -->
E18: Inputs | F18: Input Amount | G18: Input Units | H18: Outputs | I18: Output Amount | J18: Output Units | K18: Process Name | L18: Existing Facilities
E19: =IF('SAF Filters'!$J$37="Y",Notes!AG16,"") -> FOG | F19: =IF('SAF Filters'!$J$37="Y",Notes!AH16,"") -> 1 | G19: =IF('SAF Filters'!$J$37="Y",Notes!AI16,"") -> tons | H19: =IF('SAF Filters'!$J$37="Y",Notes!AJ16,"") -> SAF | I19: =IF('SAF Filters'!$J$37="Y",Notes!AK16,"") -> 127.21129 | J19: =IF('SAF Filters'!$J$37="Y",Notes!AL16,"") -> gallon | K19: =IF('SAF Filters'!$J$37="Y",Notes!AM16,"") -> 0 | L19: =IF('SAF Filters'!$J$37="Y",Notes!AN16,"") -> 0

Sheet Facilities and Amounts
A1: For Review Only
A2: DO NOT EDIT. This worksheet auto-populates based on selections in the SAF Filters tab. The facilities and amounts on this sheet are presented for user reference only.
A3: If needed, you can customize this information in the CSV files created after running the Scenario Setup Tool.
A5: Facilities
A6: Required for ALL facility types --> | D6: Required for SOME facility types --> | I6: Fully optional -->
A7: Facility Type | B7: Facility Name | C7: Commodity or Process | D7: Max Amount | E7: Units | F7: Min Amount | G7: Min Aggregation | H7: Build Cost | I7: Schedule | J7: Access Cost | K7: Unmet Demand Penalty
A8: =IF(Notes!BY4="","",Notes!BY4) -> processor | B8: =IF(Notes!BZ4="","",Notes!BZ4) -> cand_HEFA_FOG | C8: =IF(Notes!CA4="","",Notes!CA4) -> makeSAF | D8: =IF(Notes!CB4="","",Notes!CB4) -> 1142151.8 | E8: =IF(Notes!CC4="","",Notes!CC4) -> tons | F8: =IF(Notes!CD4="","",Notes!CD4) -> 571075.88 | G8: =IF(Notes!CE4="","",Notes!CE4) -> 114215.18 | H8: =IF(Notes!CF4="","",Notes!CF4) -> 32231836
A9: =IF(Notes!BY5="","",Notes!BY5) -> processor | B9: =IF(Notes!BZ5="","",Notes!BZ5) -> Ergon Asphalt & Emulsions Inc 2 | C9: =IF(Notes!CA5="","",Notes!CA5) -> blendSAF | D9: =IF(Notes!CB5="","",Notes!CB5) | E9: =IF(Notes!CC5="","",Notes!CC5) | F9: =IF(Notes!CD5="","",Notes!CD5) | G9: =IF(Notes!CE5="","",Notes!CE5) | H9: =IF(Notes!CF5="","",Notes!CF5)
A10: =IF(Notes!BY6="","",Notes!BY6) -> processor | B10: =IF(Notes!BZ6="","",Notes!BZ6) -> Sinclair Oil Corp 1 | C10: =IF(Notes!CA6="","",Notes!CA6) -> blendSAF | D10: =IF(Notes!CB6="","",Notes!CB6) | E10: =IF(Notes!CC6="","",Notes!CC6) | F10: =IF(Notes!CD6="","",Notes!CD6) | G10: =IF(Notes!CE6="","",Notes!CE6) | H10: =IF(Notes!CF6="","",Notes!CF6)
A11: =IF(Notes!BY7="","",Notes!BY7) -> processor | B11: =IF(Notes!BZ7="","",Notes!BZ7) -> Sinclair Oil Corp 3 | C11: =IF(Notes!CA7="","",Notes!CA7) -> blendSAF | D11: =IF(Notes!CB7="","",Notes!CB7) | E11: =IF(Notes!CC7="","",Notes!CC7) | F11: =IF(Notes!CD7="","",Notes!CD7) | G11: =IF(Notes!CE7="","",Notes!CE7) | H11: =IF(Notes!CF7="","",Notes!CF7)
A12: =IF(Notes!BY8="","",Notes!BY8) -> processor | B12: =IF(Notes!BZ8="","",Notes!BZ8) -> Sinclair Oil Corp 2 | C12: =IF(Notes!CA8="","",Notes!CA8) -> blendSAF | D12: =IF(Notes!CB8="","",Notes!CB8) | E12: =IF(Notes!CC8="","",Notes!CC8) | F12: =IF(Notes!CD8="","",Notes!CD8) | G12: =IF(Notes!CE8="","",Notes!CE8) | H12: =IF(Notes!CF8="","",Notes!CF8)
A13: =IF(Notes!BY9="","",Notes!BY9) -> processor | B13: =IF(Notes!BZ9="","",Notes!BZ9) -> Andeavor Logistics Lp 7 | C13: =IF(Notes!CA9="","",Notes!CA9) -> blendSAF | D13: =IF(Notes!CB9="","",Notes!CB9) | E13: =IF(Notes!CC9="","",Notes!CC9) | F13: =IF(Notes!CD9="","",Notes!CD9) | G13: =IF(Notes!CE9="","",Notes!CE9) | H13: =IF(Notes!CF9="","",Notes!CF9)
A14: =IF(Notes!BY10="","",Notes!BY10) -> processor | B14: =IF(Notes!BZ10="","",Notes!BZ10) -> Andeavor Logistics Lp 6 | C14: =IF(Notes!CA10="","",Notes!CA10) -> blendSAF | D14: =IF(Notes!CB10="","",Notes!CB10) | E14: =IF(Notes!CC10="","",Notes!CC10) | F14: =IF(Notes!CD10="","",Notes!CD10) | G14: =IF(Notes!CE10="","",Notes!CE10) | H14: =IF(Notes!CF10="","",Notes!CF10)
A15: =IF(Notes!BY11="","",Notes!BY11) -> processor | B15: =IF(Notes!BZ11="","",Notes!BZ11) -> Andeavor Logistics Lp 18 | C15: =IF(Notes!CA11="","",Notes!CA11) -> blendSAF | D15: =IF(Notes!CB11="","",Notes!CB11) | E15: =IF(Notes!CC11="","",Notes!CC11) | F15: =IF(Notes!CD11="","",Notes!CD11) | G15: =IF(Notes!CE11="","",Notes!CE11) | H15: =IF(Notes!CF11="","",Notes!CF11)
A16: =IF(Notes!BY12="","",Notes!BY12) -> processor | B16: =IF(Notes!BZ12="","",Notes!BZ12) -> Christensen Inc | C16: =IF(Notes!CA12="","",Notes!CA12) -> blendSAF | D16: =IF(Notes!CB12="","",Notes!CB12) | E16: =IF(Notes!CC12="","",Notes!CC12) | F16: =IF(Notes!CD12="","",Notes!CD12) | G16: =IF(Notes!CE12="","",Notes!CE12) | H16: =IF(Notes!CF12="","",Notes!CF12)
A17: =IF(Notes!BY13="","",Notes!BY13) -> processor | B17: =IF(Notes!BZ13="","",Notes!BZ13) -> Chevron Usa Inc Willbridge | C17: =IF(Notes!CA13="","",Notes!CA13) -> blendSAF | D17: =IF(Notes!CB13="","",Notes!CB13) | E17: =IF(Notes!CC13="","",Notes!CC13) | F17: =IF(Notes!CD13="","",Notes!CD13) | G17: =IF(Notes!CE13="","",Notes!CE13) | H17: =IF(Notes!CF13="","",Notes!CF13)
A18: =IF(Notes!BY14="","",Notes!BY14) -> processor | B18: =IF(Notes!BZ14="","",Notes!BZ14) -> Tlp Management Services Llc 3 | C18: =IF(Notes!CA14="","",Notes!CA14) -> blendSAF | D18: =IF(Notes!CB14="","",Notes!CB14) | E18: =IF(Notes!CC14="","",Notes!CC14) | F18: =IF(Notes!CD14="","",Notes!CD14) | G18: =IF(Notes!CE14="","",Notes!CE14) | H18: =IF(Notes!CF14="","",Notes!CF14)
A19: =IF(Notes!BY15="","",Notes!BY15) -> processor | B19: =IF(Notes!BZ15="","",Notes!BZ15) -> Phillips 66 Company 16 | C19: =IF(Notes!CA15="","",Notes!CA15) -> blendSAF | D19: =IF(Notes!CB15="","",Notes!CB15) | E19: =IF(Notes!CC15="","",Notes!CC15) | F19: =IF(Notes!CD15="","",Notes!CD15) | G19: =IF(Notes!CE15="","",Notes!CE15) | H19: =IF(Notes!CF15="","",Notes!CF15)
... A2000: =IF(Notes!BY1996="","",Notes!BY1996) | B2000: =IF(Notes!BZ1996="","",Notes!BZ1996) | C2000: =IF(Notes!CA1996="","",Notes!CA1996) | D2000: =IF(Notes!CB1996="","",Notes!CB1996) | E2000: =IF(Notes!CC1996="","",Notes!CC1996) | F2000: =IF(Notes!CD1996="","",Notes!CD1996) | G2000: =IF(Notes!CE1996="","",Notes!CE1996) | H2000: =IF(Notes!CF1996="","",Notes!CF1996)

Sheet SAF_Scenario
A1: Scenario | B1: Filtered
A2: Near-term | B2: =SIGN(SUBTOTAL(3,A2)) -> 0 | AD2: Commodities Table | AG2: Processes Table | BY2: Facilites and Amounts Table
A3: Mature-market medium | B3: =SIGN(SUBTOTAL(3,A3)) -> 0
A4: Mature-market low | B4: =SIGN(SUBTOTAL(3,A4)) -> 0
A5: Mature-market high | B5: =SIGN(SUBTOTAL(3,A5)) -> 1
A6: Emerging | B6: =SIGN(SUBTOTAL(3,A6)) -> 0

Sheet SAF_State
A1: State | B1: Filtered
A2: Alabama | B2: =SIGN(SUBTOTAL(3,A2)) -> 0 | AB2: Commodities Table | AE2: Processes Table | BW2: Facilites and Amounts Table
A3: Arizona | B3: =SIGN(SUBTOTAL(3,A3)) -> 0
A4: Arkansas | B4: =SIGN(SUBTOTAL(3,A4)) -> 0
A5: California | B5: =SIGN(SUBTOTAL(3,A5)) -> 0
A6: Colorado | B6: =SIGN(SUBTOTAL(3,A6)) -> 0
A7: Connecticut | B7: =SIGN(SUBTOTAL(3,A7)) -> 0
A8: Delaware | B8: =SIGN(SUBTOTAL(3,A8)) -> 0
A9: District of Columbia | B9: =SIGN(SUBTOTAL(3,A9)) -> 0
A10: Florida | B10: =SIGN(SUBTOTAL(3,A10)) -> 0
A11: Georgia | B11: =SIGN(SUBTOTAL(3,A11)) -> 0
A12: Idaho | B12: =SIGN(SUBTOTAL(3,A12)) -> 1
A13: Illinois | B13: =SIGN(SUBTOTAL(3,A13)) -> 0
A14: Indiana | B14: =SIGN(SUBTOTAL(3,A14)) -> 0
... A50: Wyoming | B50: =SIGN(SUBTOTAL(3,A50)) -> 0

Sheet SAF_Cand_Refinery
A1: Commodity | B1: Resource | C1: Phase | D1: Conversion Process | E1: Nth/Pioneer | F1: Filtered | G1: Input Amount | H1: Input Units | I1: Output | J1: Output Amount | K1: Output Units | L1: Facility Type | M1: Facility Name | N1: Commodity or Process | O1: Max Amount | P1: Units | Q1: Min Amount | R1: Min Aggregation | S1: Build Cost
A2: Ag processing waste | B2: Cotton gin trash | C2: solid | D2: Fischer-Tropsch | E2: Nth | F2: =SIGN(SUBTOTAL(3,A2)) -> 0 | G2: 1 | H2: tons | I2: SAF | J2: 15.605328 | K2: gallon | L2: processor | M2: cand_FT_Ag | N2: makeSAF | O2: 2031398.5 | P2: tons | Q2: =SAF_Cand_Refinery[[#This Row],[Max Amount]]*0.5 -> 1015699.2 | R2: =SAF_Cand_Refinery[[#This Row],[Max Amount]]*0.1 -> 203139.85 | S2: 1.0856661e+08 | BX2: Facilites and Amounts Table
A3: Ag processing waste | B3: Cotton gin trash | C3: solid | D3: Fischer-Tropsch | E3: Pioneer | F3: =SIGN(SUBTOTAL(3,A3)) -> 0 | G3: 1 | H3: tons | I3: SAF | J3: 15.605328 | K3: gallon | L3: processor | M3: cand_FT_Ag | N3: makeSAF | O3: 677132.83 | P3: tons | Q3: =SAF_Cand_Refinery[[#This Row],[Max Amount]]*0.5 -> 338566.42 | R3: =SAF_Cand_Refinery[[#This Row],[Max Amount]]*0.1 -> 67713.283 | S3: 91155662
A4: Ag processing waste | B4: Cotton gin trash | C4: solid | D4: Pyrolysis | E4: Nth | F4: =SIGN(SUBTOTAL(3,A4)) -> 0 | G4: 1 | H4: tons | I4: SAF | J4: 26.333991 | K4: gallon | L4: processor | M4: cand_Py_Ag | N4: makeSAF | O4: 1805687.6 | P4: tons | Q4: =SAF_Cand_Refinery[[#This Row],[Max Amount]]*0.5 -> 902843.78 | R4: =SAF_Cand_Refinery[[#This Row],[Max Amount]]*0.1 -> 180568.76 | S4: 77989532
A5: Ag processing waste | B5: Cotton gin trash | C5: solid | D5: Pyrolysis | E5: Pioneer | F5: =SIGN(SUBTOTAL(3,A5)) -> 0 | G5: 1 | H5: tons | I5: SAF | J5: 23.407992 | K5: gallon | L5: processor | M5: cand_Py_Ag | N5: makeSAF | O5: 451421.89 | P5: tons | Q5: =SAF_Cand_Refinery[[#This Row],[Max Amount]]*0.5 -> 225710.94 | R5: =SAF_Cand_Refinery[[#This Row],[Max Amount]]*0.1 -> 45142.189 | S5: 44534613
A6: Ag processing waste | B6: Rice hulls | C6: solid | D6: Fischer-Tropsch | E6: Nth | F6: =SIGN(SUBTOTAL(3,A6)) -> 0 | G6: 1 | H6: tons | I6: SAF | J6: 15.605328 | K6: gallon | L6: processor | M6: cand_FT_Ag | N6: makeSAF | O6: 2031398.5 | P6: tons | Q6: =SAF_Cand_Refinery[[#This Row],[Max Amount]]*0.5 -> 1015699.2 | R6: =SAF_Cand_Refinery[[#This Row],[Max Amount]]*0.1 -> 203139.85 | S6: 1.0856661e+08
A7: Ag processing waste | B7: Rice hulls | C7: solid | D7: Fischer-Tropsch | E7: Pioneer | F7: =SIGN(SUBTOTAL(3,A7)) -> 0 | G7: 1 | H7: tons | I7: SAF | J7: 15.605328 | K7: gallon | L7: processor | M7: cand_FT_Ag | N7: makeSAF | O7: 677132.83 | P7: tons | Q7: =SAF_Cand_Refinery[[#This Row],[Max Amount]]*0.5 -> 338566.42 | R7: =SAF_Cand_Refinery[[#This Row],[Max Amount]]*0.1 -> 67713.283 | S7: 91155662
A8: Ag processing waste | B8: Rice hulls | C8: solid | D8: Pyrolysis | E8: Nth | F8: =SIGN(SUBTOTAL(3,A8)) -> 0 | G8: 1 | H8: tons | I8: SAF | J8: 26.333991 | K8: gallon | L8: processor | M8: cand_Py_Ag | N8: makeSAF | O8: 1805687.6 | P8: tons | Q8: =SAF_Cand_Refinery[[#This Row],[Max Amount]]*0.5 -> 902843.78 | R8: =SAF_Cand_Refinery[[#This Row],[Max Amount]]*0.1 -> 180568.76 | S8: 77989532
A9: Ag processing waste | B9: Rice hulls | C9: solid | D9: Pyrolysis | E9: Pioneer | F9: =SIGN(SUBTOTAL(3,A9)) -> 0 | G9: 1 | H9: tons | I9: SAF | J9: 23.407992 | K9: gallon | L9: processor | M9: cand_Py_Ag | N9: makeSAF | O9: 451421.89 | P9: tons | Q9: =SAF_Cand_Refinery[[#This Row],[Max Amount]]*0.5 -> 225710.94 | R9: =SAF_Cand_Refinery[[#This Row],[Max Amount]]*0.1 -> 45142.189 | S9: 44534613
A10: Agricultural residues | B10: Barley straw | C10: solid | D10: Fischer-Tropsch | E10: Nth | F10: =SIGN(SUBTOTAL(3,A10)) -> 0 | G10: 1 | H10: tons | I10: SAF | J10: 15.605328 | K10: gallon | L10: processor | M10: cand_FT_Ag | N10: makeSAF | O10: 2031398.5 | P10: tons | Q10: =SAF_Cand_Refinery[[#This Row],[Max Amount]]*0.5 -> 1015699.2 | R10: =SAF_Cand_Refinery[[#This Row],[Max Amount]]*0.1 -> 203139.85 | S10: 1.0856661e+08
A11: Agricultural residues | B11: Barley straw | C11: solid | D11: Fischer-Tropsch | E11: Pioneer | F11: =SIGN(SUBTOTAL(3,A11)) -> 0 | G11: 1 | H11: tons | I11: SAF | J11: 15.605328 | K11: gallon | L11: processor | M11: cand_FT_Ag | N11: makeSAF | O11: 677132.83 | P11: tons | Q11: =SAF_Cand_Refinery[[#This Row],[Max Amount]]*0.5 -> 338566.42 | R11: =SAF_Cand_Refinery[[#This Row],[Max Amount]]*0.1 -> 67713.283 | S11: 91155662
A12: Agricultural residues | B12: Barley straw | C12: solid | D12: Pyrolysis | E12: Nth | F12: =SIGN(SUBTOTAL(3,A12)) -> 0 | G12: 1 | H12: tons | I12: SAF | J12: 26.333991 | K12: gallon | L12: processor | M12: cand_Py_Ag | N12: makeSAF | O12: 1805687.6 | P12: tons | Q12: =SAF_Cand_Refinery[[#This Row],[Max Amount]]*0.5 -> 902843.78 | R12: =SAF_Cand_Refinery[[#This Row],[Max Amount]]*0.1 -> 180568.76 | S12: 77989532
A13: Agricultural residues | B13: Barley straw | C13: solid | D13: Pyrolysis | E13: Pioneer | F13: =SIGN(SUBTOTAL(3,A13)) -> 0 | G13: 1 | H13: tons | I13: SAF | J13: 23.407992 | K13: gallon | L13: processor | M13: cand_Py_Ag | N13: makeSAF | O13: 451421.89 | P13: tons | Q13: =SAF_Cand_Refinery[[#This Row],[Max Amount]]*0.5 -> 225710.94 | R13: =SAF_Cand_Refinery[[#This Row],[Max Amount]]*0.1 -> 45142.189 | S13: 44534613
A14: Agricultural residues | B14: Corn stover | C14: solid | D14: Fischer-Tropsch | E14: Nth | F14: =SIGN(SUBTOTAL(3,A14)) -> 0 | G14: 1 | H14: tons | I14: SAF | J14: 15.605328 | K14: gallon | L14: processor | M14: cand_FT_Ag | N14: makeSAF | O14: 2031398.5 | P14: tons | Q14: =SAF_Cand_Refinery[[#This Row],[Max Amount]]*0.5 -> 1015699.2 | R14: =SAF_Cand_Refinery[[#This Row],[Max Amount]]*0.1 -> 203139.85 | S14: 1.0856661e+08
... A157: Woody energy crops | B157: Willow | C157: solid | D157: Pyrolysis | E157: Pioneer | F157: =SIGN(SUBTOTAL(3,A157)) -> 0 | G157: 1 | H157: tons | I157: SAF | J157: 25.637325 | K157: gallon | L157: processor | M157: cand_Py_EnergyWoody | N157: makeSAF | O157: 412167.81 | P157: tons | Q157: =SAF_Cand_Refinery[[#This Row],[Max Amount]]*0.5 -> 206083.91 | R157: =SAF_Cand_Refinery[[#This Row],[Max Amount]]*0.1 -> 41216.781 | S157: 42735961

Sheet SAF_Existing_Refinery
A1: Company | B1: City | C1: State | D1: Feedstock | E1: Process | F1: Input | G1: Status | H1: Filtered | I1: Facility Type | J1: Facility Name | K1: Commodity or Process | L1: Max Amount | M1: Units | N1: Min Amount | O1: Min Aggregation | P1: Build Cost
A2: Aemetis | B2: Riverbank | C2: California | D2: FOG | E2: HEFA | F2: FOG | G2: Proposed/Under Development | H2: =SIGN(SUBTOTAL(3,A2)) -> 0 | I2: processor | J2: Aemetis | K2: makeSAF_Existing | L2: 707484.37 | M2: tons | BY2: Facilites and Amounts Table
A3: Aemetis | B3: Riverbank | C3: California | D3: Intermediate oilseeds | E3: HEFA | F3: FOG | G3: Proposed/Under Development | H3: =SIGN(SUBTOTAL(3,A3)) -> 0 | I3: processor | J3: Aemetis | K3: makeSAF_Existing | L3: 707484.37 | M3: tons
A4: Chevron USA Inc. | B4: El Segundo | C4: California | D4: Intermediate oilseeds | E4: HEFA | F4: Soybean Oil | G4: Under Construction/Conversion | H4: =SIGN(SUBTOTAL(3,A4)) -> 0 | I4: processor | J4: Chevron Usa Inc. | K4: makeSAF_Existing | L4: 243689.06 | M4: tons
A5: CVR Energy Inc. - Coffeyville | B5: Coffeyville | C5: Kansas | D5: Intermediate oilseeds | E5: HEFA | F5: Soybean Oil | G5: Proposed/Under Development | H5: =SIGN(SUBTOTAL(3,A5)) -> 0 | I5: processor | J5: CVR Energy Inc. - Coffeyville | K5: makeSAF_Existing | L5: 3930468.7 | M5: tons
A6: Gron Fuel LLC | B6: Baton Rouge | C6: Louisiana | D6: FOG | E6: HEFA | F6: FOG | G6: Proposed/Under Development | H6: =SIGN(SUBTOTAL(3,A6)) -> 0 | I6: processor | J6: Gron Fuel Llc | K6: makeSAF_Existing | L6: 7074843.7 | M6: tons
A7: Gron Fuel LLC | B7: Baton Rouge | C7: Louisiana | D7: Intermediate oilseeds | E7: HEFA | F7: FOG | G7: Proposed/Under Development | H7: =SIGN(SUBTOTAL(3,A7)) -> 0 | I7: processor | J7: Gron Fuel Llc | K7: makeSAF_Existing | L7: 7074843.7 | M7: tons
A8: Montana Renewables (Calumet) | B8: Great Falls | C8: Montana | D8: FOG | E8: HEFA | F8: Soybean Oil | G8: Operational | H8: =SIGN(SUBTOTAL(3,A8)) -> 1 | I8: processor | J8: Montana Renewables (Calumet) | K8: makeSAF_Existing | L8: 1808015.6 | M8: tons
A9: Montana Renewables (Calumet) | B9: Great Falls | C9: Montana | D9: Intermediate oilseeds | E9: HEFA | F9: Soybean Oil | G9: Operational | H9: =SIGN(SUBTOTAL(3,A9)) -> 1 | I9: processor | J9: Montana Renewables (Calumet) | K9: makeSAF_Existing | L9: 1808015.6 | M9: tons
A10: Next Renewable Fuels Inc. | B10: Clatskanie | C10: Oregon | D10: FOG | E10: HEFA | F10: FOG | G10: Proposed/Under Development | H10: =SIGN(SUBTOTAL(3,A10)) -> 1 | I10: processor | J10: Next Renewable Fuels Inc. | K10: makeSAF_Existing | L10: 4700840.6 | M10: tons
A11: Next Renewable Fuels Inc. | B11: Clatskanie | C11: Oregon | D11: Intermediate oilseeds | E11: HEFA | F11: FOG | G11: Proposed/Under Development | H11: =SIGN(SUBTOTAL(3,A11)) -> 1 | I11: processor | J11: Next Renewable Fuels Inc. | K11: makeSAF_Existing | L11: 4700840.6 | M11: tons
A12: Phillips 66 - Rodeo Renewed | B12: Rodeo | C12: California | D12: FOG | E12: HEFA | F12: FOG | G12: Proposed/Under Development Conversion | H12: =SIGN(SUBTOTAL(3,A12)) -> 0 | I12: processor | J12: Phillips 66 - Rodeo Renewed | K12: makeSAF_Existing | L12: 5345437.5 | M12: tons
A13: Phillips 66 - Rodeo Renewed | B13: Rodeo | C13: California | D13: Intermediate oilseeds | E13: HEFA | F13: FOG | G13: Proposed/Under Development Conversion | H13: =SIGN(SUBTOTAL(3,A13)) -> 0 | I13: processor | J13: Phillips 66 - Rodeo Renewed | K13: makeSAF_Existing | L13: 5345437.5 | M13: tons
A14: ReadiFuels-Iowa LLC | B14: Sioux Center | C14: Iowa | D14: FOG | E14: HEFA | F14: FOG | G14: Proposed/Under Development | H14: =SIGN(SUBTOTAL(3,A14)) -> 0 | I14: processor | J14: Readifuels-Iowa Llc | K14: makeSAF_Existing | L14: 282993.75 | M14: tons
... A21: World Energy - Paramount | B21: Paramount | C21: California | D21: Intermediate oilseeds | E21: HEFA | F21: FOG | G21: Under Construction/Expansion | H21: =SIGN(SUBTOTAL(3,A21)) -> 0 | I21: processor | J21: World Energy - Paramount | K21: makeSAF_Existing | L21: 2672718.7 | M21: tons

Sheet SAF_Blender
A1: State | B1: City | C1: Terminal Name | D1: Filtered | E1: Facility Type | F1: Facility Name | G1: Commodity or Process | H1: Max Amount | I1: Units | J1: Min Amount | K1: Min Aggregation | L1: Build Cost
A2: Alabama | B2: Birmingham | C2: Chevron Usa Inc Birmingham | D2: =SIGN(SUBTOTAL(3,E2)) -> 0 | E2: processor | F2: Chevron Usa Inc Birmingham | G2: blendSAF | CA2: Facilites and Amounts Table
A3: Alabama | B3: Chickasaw | C3: Petroleum Fuel & Terminal Co | D3: =SIGN(SUBTOTAL(3,E3)) -> 0 | E3: processor | F3: Petroleum Fuel & Terminal Co 4 | G3: blendSAF
A4: Alabama | B4: Mobile | C4: Petroleum Fuel & Terminal Co | D4: =SIGN(SUBTOTAL(3,E4)) -> 0 | E4: processor | F4: Petroleum Fuel & Terminal Co 10 | G4: blendSAF
A5: Alabama | B5: Birmingham | C5: Ergon Asphalt & Emulsions Inc | D5: =SIGN(SUBTOTAL(3,E5)) -> 0 | E5: processor | F5: Ergon Asphalt & Emulsions Inc 1 | G5: blendSAF
A6: Alabama | B6: Birmingham | C6: Circle K Terminal Alabama Llc | D6: =SIGN(SUBTOTAL(3,E6)) -> 0 | E6: processor | F6: Circle K Terminal Alabama Llc | G6: blendSAF
A7: Alabama | B7: Anniston | C7: Murphy Oil Usa Inc | D7: =SIGN(SUBTOTAL(3,E7)) -> 0 | E7: processor | F7: Murphy Oil Usa Inc 50 | G7: blendSAF
A8: Alabama | B8: Montgomery | C8: Murphy Oil Usa Inc | D8: =SIGN(SUBTOTAL(3,E8)) -> 0 | E8: processor | F8: Murphy Oil Usa Inc 54 | G8: blendSAF
A9: Alabama | B9: Sheffield | C9: Murphy Oil Usa Inc | D9: =SIGN(SUBTOTAL(3,E9)) -> 0 | E9: processor | F9: Murphy Oil Usa Inc 55 | G9: blendSAF
A10: Alabama | B10: Montgomery | C10: Us Venture Inc | D10: =SIGN(SUBTOTAL(3,E10)) -> 0 | E10: processor | F10: Us Venture Inc 24 | G10: blendSAF
A11: Alabama | B11: Birmingham | C11: Buckeye Terminals Llc | D11: =SIGN(SUBTOTAL(3,E11)) -> 0 | E11: processor | F11: Buckeye Terminals Llc 26 | G11: blendSAF
A12: Alabama | B12: Montgomery | C12: Buckeye Terminals Llc | D12: =SIGN(SUBTOTAL(3,E12)) -> 0 | E12: processor | F12: Buckeye Terminals Llc 71 | G12: blendSAF
A13: Alabama | B13: Birmingham | C13: Buckeye Se Terminals Lp | D13: =SIGN(SUBTOTAL(3,E13)) -> 0 | E13: processor | F13: Buckeye Se Terminals Lp 3 | G13: blendSAF
A14: Alabama | B14: Birmingham | C14: Sunoco Llc | D14: =SIGN(SUBTOTAL(3,E14)) -> 0 | E14: processor | F14: Sunoco Llc 3 | G14: blendSAF
... A1384: Wyoming | B1384: Cheyenne | C1384: Magellan Pipeline Co Lp | D1384: =SIGN(SUBTOTAL(3,E1384)) -> 0 | E1384: processor | F1384: Magellan Pipeline Co Lp 5 | G1384: blendSAF

Sheet SAF_Airport
A1: State | B1: City | C1: Airport Code | D1: FAA Hub Size | E1: Filtered | F1: Facility Type | G1: Facility Name | H1: Commodity or Process | I1: Max Amount | J1: Units | K1: Min Amount | L1: Min Aggregation | M1: Build Cost
A2: Pennsylvania | B2: Allentown | C2: ABE | D2: Nonhub | E2: =SIGN(SUBTOTAL(3,F2)) -> 0 | F2: ultimate_destination | G2: ABE | H2: fuel_blend | I2: 14000000 | J2: gallons | AC2: Commodities Table | AF2: Processes Table | BX2: Facilites and Amounts Table
A3: New Mexico | B3: Albuquerque | C3: ABQ | D3: Medium | E3: =SIGN(SUBTOTAL(3,F3)) -> 0 | F3: ultimate_destination | G3: ABQ | H3: fuel_blend | I3: 29000000 | J3: gallons
A4: Texas | B4: Fort Worth | C4: AFW | D4: Nonprimary | E4: =SIGN(SUBTOTAL(3,F4)) -> 0 | F4: ultimate_destination | G4: AFW | H4: fuel_blend | I4: 3000000 | J4: gallons
A5: New York | B5: Albany | C5: ALB | D5: Small | E5: =SIGN(SUBTOTAL(3,F5)) -> 0 | F5: ultimate_destination | G5: ALB | H5: fuel_blend | I5: 23000000 | J5: gallons
A6: Alaska | B6: Anchorage | C6: ANC | D6: Medium | E6: =SIGN(SUBTOTAL(3,F6)) -> 0 | F6: ultimate_destination | G6: ANC | H6: fuel_blend | I6: 880000000 | J6: gallons
A7: Georgia | B7: Atlanta | C7: ATL | D7: Large | E7: =SIGN(SUBTOTAL(3,F7)) -> 0 | F7: ultimate_destination | G7: ATL | H7: fuel_blend | I7: 1027000000 | J7: gallons
A8: Texas | B8: Austin | C8: AUS | D8: Large | E8: =SIGN(SUBTOTAL(3,F8)) -> 0 | F8: ultimate_destination | G8: AUS | H8: fuel_blend | I8: 192000000 | J8: gallons
A9: North Carolina | B9: Asheville | C9: AVL | D9: Small | E9: =SIGN(SUBTOTAL(3,F9)) -> 0 | F9: ultimate_destination | G9: AVL | H9: fuel_blend | I9: 14000000 | J9: gallons
A10: Connecticut | B10: Windsor Locks | C10: BDL | D10: Medium | E10: =SIGN(SUBTOTAL(3,F10)) -> 0 | F10: ultimate_destination | G10: BDL | H10: fuel_blend | I10: 57000000 | J10: gallons
A11: Alabama | B11: Birmingham | C11: BHM | D11: Small | E11: =SIGN(SUBTOTAL(3,F11)) -> 0 | F11: ultimate_destination | G11: BHM | H11: fuel_blend | I11: 24000000 | J11: gallons
A12: Tennessee | B12: Nashville | C12: BNA | D12: Large | E12: =SIGN(SUBTOTAL(3,F12)) -> 0 | F12: ultimate_destination | G12: BNA | H12: fuel_blend | I12: 175000000 | J12: gallons
A13: Idaho | B13: Boise | C13: BOI | D13: Medium | E13: =SIGN(SUBTOTAL(3,F13)) -> 0 | F13: ultimate_destination | G13: BOI | H13: fuel_blend | I13: 32000000 | J13: gallons
A14: Massachusetts | B14: Boston | C14: BOS | D14: Large | E14: =SIGN(SUBTOTAL(3,F14)) -> 0 | F14: ultimate_destination | G14: BOS | H14: fuel_blend | I14: 557000000 | J14: gallons
... A126: Arkansas | B126: Fayetteville/Springdale/ | C126: XNA | D126: Small | E126: =SIGN(SUBTOTAL(3,F126)) -> 0 | F126: ultimate_destination | G126: XNA | H126: fuel_blend | I126: 18000000 | J126: gallons

Sheet Notes
A1: Data Validation Checks | E1: Drop-Down Menus | O1: Input Commodity | P1: Process | Q1: Existing Facilities | R1: Phase | S1: Max Transport Distance | V1: Process Name | W1: Input Units | X1: Allowed Units | Z1: SAF Helper Tables ---> | AW1: Note: Will only be used if "Existing Refineries" in SAF filters is set to "Y"
A2: Configuration Tab | E2: True/False | F2: Solid Units List | G2: Liquid Units List | H2: Solid and Liquid Units List | I2: Distance Units List | J2: Facility Types | K2: Phase | L2: Yes/No | M2: Processes | O2: {=_xlfn.UNIQUE(_xlfn._xlws.FILTER(_xlfn._xlws.FILTER('Commodities and Processes'!E6:L9986,('Commodities and Processes'!E6:E9986<>"Process name:")*('Commodities and Processes'!E6:E9986<>"Inputs")*('Commodities and Processes'!E6:E9986<>"Existing facilities:")*('Commodities and Processes'!E6:E9986<>"")),{1,0,0,0,0,0,1,1}))} -> FOG | P2: makeSAF | Q2: N | R2: =IF(ISBLANK(O2),"",VLOOKUP(O2,'Commodities and Processes'!A:C,2,FALSE)) -> solid | S2: =IF(ISBLANK(O2),"",VLOOKUP(O2,'Commodities and Processes'!A:C,3,FALSE)) -> 500 | V2: {=_xlfn.UNIQUE(_xlfn._xlws.FILTER(P2:P2000,P2:P2000<>""))} -> makeSAF | W2: {=IF(ISBLANK(V2),"",_xlfn.CONCAT(_xlfn.UNIQUE(_xlfn._xlws.FILTER(R2:R2000,P2:P2000=V2))))} -> solid | X2: =IF(ISBLANK(V2),"",IF(W2="liquid","solidliquid","solid")) -> solid | Z2: Selected Commodity | AA2: {=INDEX(_xlfn._xlws.FILTER(SAF_Cand_Refinery[], _xlfn.TOCOL(SAF_Cand_Refinery[Filtered])=1),1,1)} -> FOG | AC2: Commodities Table | AG2: Processes Table | AN2: Candidate Refineries | AW2: Existing Refineries | BF2: Blending Facilities | BO2: Airports | BY2: Facilites and Amounts Table | CI2: Ethanol Biorefinery Checking
A3: Value | B3: Value Check | C3: Units Check | E3: TRUE | F3: tons | G3: liters | H3: tons | I3: miles | J3: raw_material_producer | K3: solid | L3: Y | M3: {=_xlfn.UNIQUE(_xlfn._xlws.FILTER('Commodities and Processes'!F:F,('Commodities and Processes'!E:E="Process name:")*('Commodities and Processes'!F:F<>"")))} -> makeSAF | O3: SAF | P3: blendSAF | Q3: Y | R3: =IF(ISBLANK(O3),"",VLOOKUP(O3,'Commodities and Processes'!A:C,2,FALSE)) -> liquid | S3: =IF(ISBLANK(O3),"",VLOOKUP(O3,'Commodities and Processes'!A:C,3,FALSE)) -> 0 | V3: blendSAF | W3: {=IF(ISBLANK(V3),"",_xlfn.CONCAT(_xlfn.UNIQUE(_xlfn._xlws.FILTER(R3:R2001,P3:P2001=V3))))} -> liquid | X3: =IF(ISBLANK(V3),"",IF(W3="liquid","solidliquid","solid")) -> solidliquid | Z3: Selected Process | AA3: {=INDEX(_xlfn._xlws.FILTER(SAF_Cand_Refinery[], _xlfn.TOCOL(SAF_Cand_Refinery[Filtered])=1),1,4)} -> HEFA | AC3: Name | AD3: Phase | AE3: Max Transport Distance | AG3: Process name: | AH3: makeSAF | AN3: Facility Type | AO3: Facility Name | AP3: Commodity or Process | AQ3: Max Amount | AR3: Units | AS3: Min Amount | AT3: Min Aggregation | AU3: Build Cost | AW3: Facility Type | AX3: Facility Name | AY3: Commodity or Process | AZ3: Max Amount | BA3: Units | BB3: Min Amount | BC3: Min Aggregation | BD3: Build Cost | BF3: Facility Type | BG3: Facility Name | BH3: Commodity or Process | BI3: Max Amount | BJ3: Units | BK3: Min Amount | BL3: Min Aggregation | BM3: Build Cost | BO3: Facility Type | BP3: Facility Name | BQ3: Commodity or Process | BR3: Max Amount | BS3: Units | BT3: Min Amount | BU3: Min Aggregation | BV3: Build Cost | BY3: Facility Type | BZ3: Facility Name | CA3: Commodity or Process | CB3: Max Amount | CC3: Units | CD3: Min Amount | CE3: Min Aggregation | CF3: Build Cost | CI3: State with Refinery | CJ3: In Filter Selection?
A4: Scenario Name | B4: string | E4: FALSE | F4: tonnes | G4: gallons | H4: tonnes | I4: meters | J4: processor | K4: liquid | L4: N | M4: blendSAF | O4: FOG | P4: 0 | Q4: 0 | R4: =IF(ISBLANK(O4),"",VLOOKUP(O4,'Commodities and Processes'!A:C,2,FALSE)) -> solid | S4: =IF(ISBLANK(O4),"",VLOOKUP(O4,'Commodities and Processes'!A:C,3,FALSE)) -> 500 | V4: 0 | W4: {=IF(ISBLANK(V4),"",_xlfn.CONCAT(_xlfn.UNIQUE(_xlfn._xlws.FILTER(R4:R2002,P4:P2002=V4))))} -> solid | X4: =IF(ISBLANK(V4),"",IF(W4="liquid","solidliquid","solid")) -> solid | Z4: Share Usable Feedstock | AA4: ='SAF Filters'!S9 -> 1 | AC4: SAF | AD4: liquid | AG4: Existing facilities: | AH4: N | AN4: {=_xlfn.UNIQUE(_xlfn._xlws.FILTER(_xlfn._xlws.FILTER(SAF_Cand_Refinery[], _xlfn.TOCOL(SAF_Cand_Refinery[Filtered])=1), {0,0,0,0,0,0,0,0,0,0,0,1,1,1,1,1,1,1,1}))} -> processor | AO4: cand_HEFA_FOG | AP4: makeSAF | AQ4: 1142151.8 | AR4: tons | AS4: 571075.88 | AT4: 114215.18 | AU4: 32231836 | AW4: {=IFERROR(_xlfn.LET(_xlpm.a, _xlfn._xlws.FILTER(_xlfn._xlws.FILTER(SAF_Existing_Refinery[], (SAF_Existing_Refinery[Filtered]=1)*(SAF_Existing_Refinery[Feedstock]=AA2)*(SAF_Existing_Refinery[Process]=AA3)),{0,0,0,0,0,0,0,0,1,1,1,1,1,1,1,1}), IF(_xlpm.a=0,"",_xlpm.a)),_xlfn.EXPAND("",1,8,""))} -> processor | AX4: Montana Renewables (Calumet) | AY4: makeSAF_Existing | AZ4: 1808015.6 | BA4: tons | BF4: {=IFERROR(_xlfn.LET(_xlpm.a, _xlfn._xlws.FILTER(_xlfn._xlws.FILTER(SAF_Blender[], SAF_Blender[Filtered]=1),{0,0,0,0,1,1,1,1,1,1,1,1}), IF(_xlpm.a=0,"",_xlpm.a)),_xlfn.EXPAND("",1,8,""))} -> processor | BG4: Ergon Asphalt & Emulsions Inc 2 | BH4: blendSAF | BO4: {=IFERROR(_xlfn.LET(_xlpm.a, _xlfn._xlws.FILTER(_xlfn._xlws.FILTER(SAF_Airport[], SAF_Airport[Filtered]=1),{0,0,0,0,0,1,1,1,1,1,1,1,1}), IF(_xlpm.a=0,"",_xlpm.a)),_xlfn.EXPAND("",1,8,""))} -> ultimate_destination | BP4: SEA | BQ4: fuel_blend | BR4: 710000000 | BS4: gallons | BY4: {=IF('SAF Filters'!J37="Y",_xlfn.VSTACK(_xlfn.ANCHORARRAY(AN4),_xlfn.ANCHORARRAY(BF4),_xlfn.ANCHORARRAY(BO4),_xlfn.ANCHORARRAY(AW4)),_xlfn.VSTACK(_xlfn.ANCHORARRAY(AN4),_xlfn.ANCHORARRAY(BF4),_xlfn.ANCHORARRAY(BO4)))} -> processor | BZ4: cand_HEFA_FOG | CA4: makeSAF | CB4: 1142151.8 | CC4: tons | CD4: 571075.88 | CE4: 114215.18 | CF4: 32231836 | CI4: South Dakota | CJ4: =COUNTIFS(SAF_State[State],Notes!CI4,SAF_State[Filtered],1) -> 0
A5: Scenario Description | B5: string | F5: pounds | G5: thousand gallons | H5: pounds | I5: kilometers | J5: ultimate_destination | M5: makeSAF_Existing | R5: =IF(ISBLANK(O5),"",VLOOKUP(O5,'Commodities and Processes'!A:C,2,FALSE)) | S5: =IF(ISBLANK(O5),"",VLOOKUP(O5,'Commodities and Processes'!A:C,3,FALSE)) | W5: {=IF(ISBLANK(V5),"",_xlfn.CONCAT(_xlfn.UNIQUE(_xlfn._xlws.FILTER(R5:R2003,P5:P2003=V5))))} | X5: =IF(ISBLANK(V5),"",IF(W5="liquid","solidliquid","solid")) | AC5: fuel_blend | AD5: liquid | AG5: Inputs | AH5: Input Amount | AI5: Input Units | AJ5: Outputs | AK5: Output Amount | AL5: Output Units | AW5: processor | AX5: Next Renewable Fuels Inc. | AY5: makeSAF_Existing | AZ5: 4700840.6 | BA5: tons | BF5: processor | BG5: Sinclair Oil Corp 1 | BH5: blendSAF | BY5: processor | BZ5: Ergon Asphalt & Emulsions Inc 2 | CA5: blendSAF | CI5: Nebraska | CJ5: =COUNTIFS(SAF_State[State],Notes!CI5,SAF_State[Filtered],1) -> 0
A6: Commodities (Solids) | B6: Solid Units List drop-down | F6: kilograms | H6: kilograms | I6: feet | R6: =IF(ISBLANK(O6),"",VLOOKUP(O6,'Commodities and Processes'!A:C,2,FALSE)) | S6: =IF(ISBLANK(O6),"",VLOOKUP(O6,'Commodities and Processes'!A:C,3,FALSE)) | W6: {=IF(ISBLANK(V6),"",_xlfn.CONCAT(_xlfn.UNIQUE(_xlfn._xlws.FILTER(R6:R2004,P6:P2004=V6))))} | X6: =IF(ISBLANK(V6),"",IF(W6="liquid","solidliquid","solid")) | AC6: {=_xlfn.UNIQUE(INDEX(_xlfn._xlws.FILTER(_xlfn._xlws.FILTER(SAF_Cand_Refinery[], _xlfn.TOCOL(SAF_Cand_Refinery[Filtered])=1), {1,0,1,0,0,0,0,0,0,0,0,0,0,0,0,0,0,0,0}),0))} -> FOG | AD6: solid | AE6: ='SAF Filters'!S17 -> 500 | AG6: {=_xlfn.UNIQUE(_xlfn._xlws.FILTER(_xlfn._xlws.FILTER(SAF_Cand_Refinery[], _xlfn.TOCOL(SAF_Cand_Refinery[Filtered])=1), {1,0,0,0,0,0,1,1,1,1,1,0,0,0,0,0,0,0,0}))} -> FOG | AH6: 1 | AI6: tons | AJ6: SAF | AK6: 127.21129 | AL6: gallon | BF6: processor | BG6: Sinclair Oil Corp 3 | BH6: blendSAF | BY6: processor | BZ6: Sinclair Oil Corp 1 | CA6: blendSAF | CI6: Iowa | CJ6: =COUNTIFS(SAF_State[State],Notes!CI6,SAF_State[Filtered],1) -> 0
A7: Commodities (Liquids) | B7: Liquid Units List drop-down | H7: liters | R7: =IF(ISBLANK(O7),"",VLOOKUP(O7,'Commodities and Processes'!A:C,2,FALSE)) | S7: =IF(ISBLANK(O7),"",VLOOKUP(O7,'Commodities and Processes'!A:C,3,FALSE)) | W7: {=IF(ISBLANK(V7),"",_xlfn.CONCAT(_xlfn.UNIQUE(_xlfn._xlws.FILTER(R7:R2005,P7:P2005=V7))))} | X7: =IF(ISBLANK(V7),"",IF(W7="liquid","solidliquid","solid")) | BF7: processor | BG7: Sinclair Oil Corp 2 | BH7: blendSAF | BY7: processor | BZ7: Sinclair Oil Corp 3 | CA7: blendSAF | CI7: Minnesota | CJ7: =COUNTIFS(SAF_State[State],Notes!CI7,SAF_State[Filtered],1) -> 0
A8: Distance | B8: Distance Units List drop-down | H8: gallons | R8: =IF(ISBLANK(O8),"",VLOOKUP(O8,'Commodities and Processes'!A:C,2,FALSE)) | S8: =IF(ISBLANK(O8),"",VLOOKUP(O8,'Commodities and Processes'!A:C,3,FALSE)) | W8: {=IF(ISBLANK(V8),"",_xlfn.CONCAT(_xlfn.UNIQUE(_xlfn._xlws.FILTER(R8:R2006,P8:P2006=V8))))} | X8: =IF(ISBLANK(V8),"",IF(W8="liquid","solidliquid","solid")) | AG8: Process name: | AH8: blendSAF | BF8: processor | BG8: Andeavor Logistics Lp 7 | BH8: blendSAF | BY8: processor | BZ8: Sinclair Oil Corp 2 | CA8: blendSAF | CI8: Michigan | CJ8: =COUNTIFS(SAF_State[State],Notes!CI8,SAF_State[Filtered],1) -> 0
A9: Currency | B9: string | H9: thousand gallons | R9: =IF(ISBLANK(O9),"",VLOOKUP(O9,'Commodities and Processes'!A:C,2,FALSE)) | S9: =IF(ISBLANK(O9),"",VLOOKUP(O9,'Commodities and Processes'!A:C,3,FALSE)) | W9: {=IF(ISBLANK(V9),"",_xlfn.CONCAT(_xlfn.UNIQUE(_xlfn._xlws.FILTER(R9:R2007,P9:P2007=V9))))} | X9: =IF(ISBLANK(V9),"",IF(W9="liquid","solidliquid","solid")) | AG9: Existing facilities: | AH9: Y | BF9: processor | BG9: Andeavor Logistics Lp 6 | BH9: blendSAF | BY9: processor | BZ9: Andeavor Logistics Lp 7 | CA9: blendSAF | CI9: Indiana | CJ9: =COUNTIFS(SAF_State[State],Notes!CI9,SAF_State[Filtered],1) -> 0
A10: RMP GIS Feature Layer | B10: file path to check with Python | R10: =IF(ISBLANK(O10),"",VLOOKUP(O10,'Commodities and Processes'!A:C,2,FALSE)) | S10: =IF(ISBLANK(O10),"",VLOOKUP(O10,'Commodities and Processes'!A:C,3,FALSE)) | W10: {=IF(ISBLANK(V10),"",_xlfn.CONCAT(_xlfn.UNIQUE(_xlfn._xlws.FILTER(R10:R2008,P10:P2008=V10))))} | X10: =IF(ISBLANK(V10),"",IF(W10="liquid","solidliquid","solid")) | AG10: Inputs | AH10: Input Amount | AI10: Input Units | AJ10: Outputs | AK10: Output Amount | AL10: Output Units | BF10: processor | BG10: Andeavor Logistics Lp 18 | BH10: blendSAF | BY10: processor | BZ10: Andeavor Logistics Lp 6 | CA10: blendSAF | CI10: Illinois | CJ10: =COUNTIFS(SAF_State[State],Notes!CI10,SAF_State[Filtered],1) -> 0
A11: Processor GIS Feature Layer (if applicable) | B11: file path to check with Python | R11: =IF(ISBLANK(O11),"",VLOOKUP(O11,'Commodities and Processes'!A:C,2,FALSE)) | S11: =IF(ISBLANK(O11),"",VLOOKUP(O11,'Commodities and Processes'!A:C,3,FALSE)) | W11: {=IF(ISBLANK(V11),"",_xlfn.CONCAT(_xlfn.UNIQUE(_xlfn._xlws.FILTER(R11:R2009,P11:P2009=V11))))} | X11: =IF(ISBLANK(V11),"",IF(W11="liquid","solidliquid","solid")) | AG11: SAF | AH11: 1 | AI11: gallons | AJ11: fuel_blend | AK11: =1/'SAF Filters'!T52 -> 2 | AL11: gallons | BF11: processor | BG11: Christensen Inc | BH11: blendSAF | BY11: processor | BZ11: Andeavor Logistics Lp 18 | CA11: blendSAF | CI11: Colorado | CJ11: =COUNTIFS(SAF_State[State],Notes!CI11,SAF_State[Filtered],1) -> 0
A12: Destination GIS Feature Layer | B12: file path to check with Python | R12: =IF(ISBLANK(O12),"",VLOOKUP(O12,'Commodities and Processes'!A:C,2,FALSE)) | S12: =IF(ISBLANK(O12),"",VLOOKUP(O12,'Commodities and Processes'!A:C,3,FALSE)) | W12: {=IF(ISBLANK(V12),"",_xlfn.CONCAT(_xlfn.UNIQUE(_xlfn._xlws.FILTER(R12:R2010,P12:P2010=V12))))} | X12: =IF(ISBLANK(V12),"",IF(W12="liquid","solidliquid","solid")) | BF12: processor | BG12: Chevron Usa Inc Willbridge | BH12: blendSAF | BY12: processor | BZ12: Christensen Inc | CA12: blendSAF | CI12: Ohio | CJ12: =COUNTIFS(SAF_State[State],Notes!CI12,SAF_State[Filtered],1) -> 0
A13: Road | B13: T/F drop-down | R13: =IF(ISBLANK(O14),"",VLOOKUP(O14,'Commodities and Processes'!A:C,2,FALSE)) | S13: =IF(ISBLANK(O13),"",VLOOKUP(O13,'Commodities and Processes'!A:C,3,FALSE)) | W13: {=IF(ISBLANK(V13),"",_xlfn.CONCAT(_xlfn.UNIQUE(_xlfn._xlws.FILTER(R13:R2011,P13:P2011=V13))))} | X13: =IF(ISBLANK(V13),"",IF(W13="liquid","solidliquid","solid")) | AG13: Process name: | AH13: makeSAF_Existing | BF13: processor | BG13: Tlp Management Services Llc 3 | BH13: blendSAF | BY13: processor | BZ13: Chevron Usa Inc Willbridge | CA13: blendSAF | CI13: Oregon | CJ13: =COUNTIFS(SAF_State[State],Notes!CI13,SAF_State[Filtered],1) -> 1
A14: Rail | B14: T/F drop-down | R14: =IF(ISBLANK(O15),"",VLOOKUP(O15,'Commodities and Processes'!A:C,2,FALSE)) | S14: =IF(ISBLANK(O14),"",VLOOKUP(O14,'Commodities and Processes'!A:C,3,FALSE)) | W14: {=IF(ISBLANK(V14),"",_xlfn.CONCAT(_xlfn.UNIQUE(_xlfn._xlws.FILTER(R14:R2012,P14:P2012=V14))))} | X14: =IF(ISBLANK(V14),"",IF(W14="liquid","solidliquid","solid")) | AG14: Existing facilities: | AH14: Y | BF14: processor | BG14: Phillips 66 Company 16 | BH14: blendSAF | BY14: processor | BZ14: Tlp Management Services Llc 3 | CA14: blendSAF | CI14: Wisconsin | CJ14: =COUNTIFS(SAF_State[State],Notes!CI14,SAF_State[Filtered],1) -> 0
A15: Water | B15: T/F drop-down | R15: =IF(ISBLANK(O15),"",VLOOKUP(O15,'Commodities and Processes'!A:C,2,FALSE)) | S15: =IF(ISBLANK(O15),"",VLOOKUP(O15,'Commodities and Processes'!A:C,3,FALSE)) | W15: {=IF(ISBLANK(V15),"",_xlfn.CONCAT(_xlfn.UNIQUE(_xlfn._xlws.FILTER(R15:R2013,P15:P2013=V15))))} | X15: =IF(ISBLANK(V15),"",IF(W15="liquid","solidliquid","solid")) | AG15: Inputs | AH15: Input Amount | AI15: Input Units | AJ15: Outputs | AK15: Output Amount | AL15: Output Units | BF15: processor | BG15: Phillips 66 3 | BH15: blendSAF | BY15: processor | BZ15: Phillips 66 Company 16 | CA15: blendSAF | CI15: Idaho | CJ15: =COUNTIFS(SAF_State[State],Notes!CI15,SAF_State[Filtered],1) -> 1
A16: Pipeline Crude | B16: T/F drop-down | R16: =IF(ISBLANK(O16),"",VLOOKUP(O16,'Commodities and Processes'!A:C,2,FALSE)) | S16: =IF(ISBLANK(O16),"",VLOOKUP(O16,'Commodities and Processes'!A:C,3,FALSE)) | W16: {=IF(ISBLANK(V16),"",_xlfn.CONCAT(_xlfn.UNIQUE(_xlfn._xlws.FILTER(R16:R2014,P16:P2014=V16))))} | X16: =IF(ISBLANK(V16),"",IF(W16="liquid","solidliquid","solid")) | AG16: {=_xlfn.UNIQUE(_xlfn._xlws.FILTER(_xlfn._xlws.FILTER(SAF_Cand_Refinery[], _xlfn.TOCOL(SAF_Cand_Refinery[Filtered])=1), {1,0,0,0,0,0,1,1,1,1,1,0,0,0,0,0,0,0,0}))} -> FOG | AH16: 1 | AI16: tons | AJ16: SAF | AK16: 127.21129 | AL16: gallon | BF16: processor | BG16: Global Co Llc 4 | BH16: blendSAF | BY16: processor | BZ16: Phillips 66 3 | CA16: blendSAF | CI16: Georgia | CJ16: =COUNTIFS(SAF_State[State],Notes!CI16,SAF_State[Filtered],1) -> 0
A17: Pipeline Prod | B17: T/F drop-down | R17: =IF(ISBLANK(O17),"",VLOOKUP(O17,'Commodities and Processes'!A:C,2,FALSE)) | S17: =IF(ISBLANK(O17),"",VLOOKUP(O17,'Commodities and Processes'!A:C,3,FALSE)) | W17: {=IF(ISBLANK(V17),"",_xlfn.CONCAT(_xlfn.UNIQUE(_xlfn._xlws.FILTER(R17:R2015,P17:P2015=V17))))} | X17: =IF(ISBLANK(V17),"",IF(W17="liquid","solidliquid","solid")) | AG17: Note: Will only be used if "Existing Refineries" in SAF filters is set to "Y" | BF17: processor | BG17: Pacific Terminal Services Inc | BH17: blendSAF | BY17: processor | BZ17: Global Co Llc 4 | CA17: blendSAF | CI17: Missouri | CJ17: =COUNTIFS(SAF_State[State],Notes!CI17,SAF_State[Filtered],1) -> 0
A18: Common Data Folder | B18: file path to check with Python | R18: =IF(ISBLANK(O18),"",VLOOKUP(O18,'Commodities and Processes'!A:C,2,FALSE)) | S18: =IF(ISBLANK(O18),"",VLOOKUP(O18,'Commodities and Processes'!A:C,3,FALSE)) | W18: {=IF(ISBLANK(V18),"",_xlfn.CONCAT(_xlfn.UNIQUE(_xlfn._xlws.FILTER(R18:R2016,P18:P2016=V18))))} | X18: =IF(ISBLANK(V18),"",IF(W18="liquid","solidliquid","solid")) | BF18: processor | BG18: Sfpp Lp 4 | BH18: blendSAF | BY18: processor | BZ18: Pacific Terminal Services Inc | CA18: blendSAF | CI18: North Dakota | CJ18: =COUNTIFS(SAF_State[State],Notes!CI18,SAF_State[Filtered],1) -> 0
A19: Network GDB | B19: file path to check with Python | R19: =IF(ISBLANK(O19),"",VLOOKUP(O19,'Commodities and Processes'!A:C,2,FALSE)) | S19: =IF(ISBLANK(O19),"",VLOOKUP(O19,'Commodities and Processes'!A:C,3,FALSE)) | W19: {=IF(ISBLANK(V19),"",_xlfn.CONCAT(_xlfn.UNIQUE(_xlfn._xlws.FILTER(R19:R2017,P19:P2017=V19))))} | X19: =IF(ISBLANK(V19),"",IF(W19="liquid","solidliquid","solid")) | BF19: processor | BG19: Kinder Morgan Portland Liquids Termi | BH19: blendSAF | BY19: processor | BZ19: Sfpp Lp 4 | CA19: blendSAF | CI19: Pennsylvania | CJ19: =COUNTIFS(SAF_State[State],Notes!CI19,SAF_State[Filtered],1) -> 0
A20: Impedance Weights CSV | B20: file path to check with Python, or "None" | R20: =IF(ISBLANK(O20),"",VLOOKUP(O20,'Commodities and Processes'!A:C,2,FALSE)) | S20: =IF(ISBLANK(O20),"",VLOOKUP(O20,'Commodities and Processes'!A:C,3,FALSE)) | W20: {=IF(ISBLANK(V20),"",_xlfn.CONCAT(_xlfn.UNIQUE(_xlfn._xlws.FILTER(R20:R2018,P20:P2018=V20))))} | X20: =IF(ISBLANK(V20),"",IF(W20="liquid","solidliquid","solid")) | BF20: processor | BG20: Mccall Oil & Chemical | BH20: blendSAF | BY20: processor | BZ20: Kinder Morgan Portland Liquids Termi | CA20: blendSAF | CI20: New York | CJ20: =COUNTIFS(SAF_State[State],Notes!CI20,SAF_State[Filtered],1) -> 0
A21: Commodity Mode CSV | B21: file path to check with Python, or "None" | R21: =IF(ISBLANK(O21),"",VLOOKUP(O21,'Commodities and Processes'!A:C,2,FALSE)) | S21: =IF(ISBLANK(O21),"",VLOOKUP(O21,'Commodities and Processes'!A:C,3,FALSE)) | W21: {=IF(ISBLANK(V21),"",_xlfn.CONCAT(_xlfn.UNIQUE(_xlfn._xlws.FILTER(R21:R2019,P21:P2019=V21))))} | X21: =IF(ISBLANK(V21),"",IF(W21="liquid","solidliquid","solid")) | BF21: processor | BG21: Nustar Energy Lp 33 | BH21: blendSAF | BY21: processor | BZ21: Mccall Oil & Chemical | CA21: blendSAF | CI21: Kansas | CJ21: =COUNTIFS(SAF_State[State],Notes!CI21,SAF_State[Filtered],1) -> 0
A22: Commodity Density CSV | B22: file path to check with Python, or "None" | R22: =IF(ISBLANK(O22),"",VLOOKUP(O22,'Commodities and Processes'!A:C,2,FALSE)) | S22: =IF(ISBLANK(O22),"",VLOOKUP(O22,'Commodities and Processes'!A:C,3,FALSE)) | W22: {=IF(ISBLANK(V22),"",_xlfn.CONCAT(_xlfn.UNIQUE(_xlfn._xlws.FILTER(R22:R2020,P22:P2020=V22))))} | X22: =IF(ISBLANK(V22),"",IF(W22="liquid","solidliquid","solid")) | BF22: processor | BG22: Equilon Enterprises Llc 3 | BH22: blendSAF | BY22: processor | BZ22: Nustar Energy Lp 33 | CA22: blendSAF | CI22: Texas | CJ22: =COUNTIFS(SAF_State[State],Notes!CI22,SAF_State[Filtered],1) -> 0
A23: Disruption CSV | B23: file path to check with Python, or "None" | R23: =IF(ISBLANK(O23),"",VLOOKUP(O23,'Commodities and Processes'!A:C,2,FALSE)) | S23: =IF(ISBLANK(O23),"",VLOOKUP(O23,'Commodities and Processes'!A:C,3,FALSE)) | W23: {=IF(ISBLANK(V23),"",_xlfn.CONCAT(_xlfn.UNIQUE(_xlfn._xlws.FILTER(R23:R2021,P23:P2021=V23))))} | X23: =IF(ISBLANK(V23),"",IF(W23="liquid","solidliquid","solid")) | BF23: processor | BG23: Tidewater Terminal Co 2 | BH23: blendSAF | BY23: processor | BZ23: Equilon Enterprises Llc 3 | CA23: blendSAF | CI23: Virginia | CJ23: =COUNTIFS(SAF_State[State],Notes!CI23,SAF_State[Filtered],1) -> 0
A24: Schedules CSV | B24: file path to check with Python, or "None" | R24: =IF(ISBLANK(O24),"",VLOOKUP(O24,'Commodities and Processes'!A:C,2,FALSE)) | S24: =IF(ISBLANK(O24),"",VLOOKUP(O24,'Commodities and Processes'!A:C,3,FALSE)) | W24: {=IF(ISBLANK(V24),"",_xlfn.CONCAT(_xlfn.UNIQUE(_xlfn._xlws.FILTER(R24:R2022,P24:P2022=V24))))} | X24: =IF(ISBLANK(V24),"",IF(W24="liquid","solidliquid","solid")) | BF24: processor | BG24: Owens Corning 11 | BH24: blendSAF | BY24: processor | BZ24: Tidewater Terminal Co 2 | CA24: blendSAF | CI24: Kentucky | CJ24: =COUNTIFS(SAF_State[State],Notes!CI24,SAF_State[Filtered],1) -> 0
A25: Detailed Emissions CSV | B25: file path to check with Python, or "None" | R25: =IF(ISBLANK(O25),"",VLOOKUP(O25,'Commodities and Processes'!A:C,2,FALSE)) | S25: =IF(ISBLANK(O25),"",VLOOKUP(O25,'Commodities and Processes'!A:C,3,FALSE)) | W25: {=IF(ISBLANK(V25),"",_xlfn.CONCAT(_xlfn.UNIQUE(_xlfn._xlws.FILTER(R25:R2023,P25:P2023=V25))))} | X25: =IF(ISBLANK(V25),"",IF(W25="liquid","solidliquid","solid")) | BF25: processor | BG25: Zenith Energy Terminals Holdings Llc | BH25: blendSAF | BY25: processor | BZ25: Owens Corning 11 | CA25: blendSAF | CI25: California | CJ25: =COUNTIFS(SAF_State[State],Notes!CI25,SAF_State[Filtered],1) -> 0
A26: Truck Base Cost (Solids) | B26: non-negative number | C26: none | R26: =IF(ISBLANK(O26),"",VLOOKUP(O26,'Commodities and Processes'!A:C,2,FALSE)) | S26: =IF(ISBLANK(O26),"",VLOOKUP(O26,'Commodities and Processes'!A:C,3,FALSE)) | W26: {=IF(ISBLANK(V26),"",_xlfn.CONCAT(_xlfn.UNIQUE(_xlfn._xlws.FILTER(R26:R2024,P26:P2024=V26))))} | X26: =IF(ISBLANK(V26),"",IF(W26="liquid","solidliquid","solid")) | BF26: processor | BG26: Reg Grays Harbor Llc | BH26: blendSAF | BY26: processor | BZ26: Zenith Energy Terminals Holdings Llc | CA26: blendSAF | CI26: Tennessee | CJ26: =COUNTIFS(SAF_State[State],Notes!CI26,SAF_State[Filtered],1) -> 0
A27: Truck Base Cost (Liquids) | B27: non-negative number | C27: none | R27: =IF(ISBLANK(O27),"",VLOOKUP(O27,'Commodities and Processes'!A:C,2,FALSE)) | S27: =IF(ISBLANK(O27),"",VLOOKUP(O27,'Commodities and Processes'!A:C,3,FALSE)) | W27: {=IF(ISBLANK(V27),"",_xlfn.CONCAT(_xlfn.UNIQUE(_xlfn._xlws.FILTER(R27:R2025,P27:P2025=V27))))} | X27: =IF(ISBLANK(V27),"",IF(W27="liquid","solidliquid","solid")) | BF27: processor | BG27: Ergon Asphalt & Emulsions Inc 11 | BH27: blendSAF | BY27: processor | BZ27: Reg Grays Harbor Llc | CA27: blendSAF | CI27: Arizona | CJ27: =COUNTIFS(SAF_State[State],Notes!CI27,SAF_State[Filtered],1) -> 0
A28: Railroad Base Cost (Solids) | B28: non-negative number | C28: none | R28: =IF(ISBLANK(O28),"",VLOOKUP(O28,'Commodities and Processes'!A:C,2,FALSE)) | S28: =IF(ISBLANK(O28),"",VLOOKUP(O28,'Commodities and Processes'!A:C,3,FALSE)) | W28: {=IF(ISBLANK(V28),"",_xlfn.CONCAT(_xlfn.UNIQUE(_xlfn._xlws.FILTER(R28:R2026,P28:P2026=V28))))} | X28: =IF(ISBLANK(V28),"",IF(W28="liquid","solidliquid","solid")) | BF28: processor | BG28: Ergon Asphalt 7 Emulsions Inc | BH28: blendSAF | BY28: processor | BZ28: Ergon Asphalt & Emulsions Inc 11 | CA28: blendSAF | CI28: Mississippi | CJ28: =COUNTIFS(SAF_State[State],Notes!CI28,SAF_State[Filtered],1) -> 0
A29: Railroad Base Cost (Liquids) | B29: non-negative number | C29: none | R29: =IF(ISBLANK(O29),"",VLOOKUP(O29,'Commodities and Processes'!A:C,2,FALSE)) | S29: =IF(ISBLANK(O29),"",VLOOKUP(O29,'Commodities and Processes'!A:C,3,FALSE)) | W29: {=IF(ISBLANK(V29),"",_xlfn.CONCAT(_xlfn.UNIQUE(_xlfn._xlws.FILTER(R29:R2027,P29:P2027=V29))))} | X29: =IF(ISBLANK(V29),"",IF(W29="liquid","solidliquid","solid")) | BF29: processor | BG29: Ergon Asphalt & Emulsions Inc 14 | BH29: blendSAF | BY29: processor | BZ29: Ergon Asphalt 7 Emulsions Inc | CA29: blendSAF
A30: Barge Base Cost (Solids) | B30: non-negative number | C30: none | R30: =IF(ISBLANK(O30),"",VLOOKUP(O30,'Commodities and Processes'!A:C,2,FALSE)) | S30: =IF(ISBLANK(O30),"",VLOOKUP(O30,'Commodities and Processes'!A:C,3,FALSE)) | W30: {=IF(ISBLANK(V30),"",_xlfn.CONCAT(_xlfn.UNIQUE(_xlfn._xlws.FILTER(R30:R2028,P30:P2028=V30))))} | X30: =IF(ISBLANK(V30),"",IF(W30="liquid","solidliquid","solid")) | BF30: processor | BG30: Tlp Management Services Llc 4 | BH30: blendSAF | BY30: processor | BZ30: Ergon Asphalt & Emulsions Inc 14 | CA30: blendSAF | CI30: Total | CJ30: =SUM(CJ4:CJ28) -> 2
A31: Barge Base Cost (Liquids) | B31: non-negative number | C31: none | R31: =IF(ISBLANK(O31),"",VLOOKUP(O31,'Commodities and Processes'!A:C,2,FALSE)) | S31: =IF(ISBLANK(O31),"",VLOOKUP(O31,'Commodities and Processes'!A:C,3,FALSE)) | W31: {=IF(ISBLANK(V31),"",_xlfn.CONCAT(_xlfn.UNIQUE(_xlfn._xlws.FILTER(R31:R2029,P31:P2029=V31))))} | X31: =IF(ISBLANK(V31),"",IF(W31="liquid","solidliquid","solid")) | BF31: processor | BG31: Seaport Sound Terminal Llc | BH31: blendSAF | BY31: processor | BZ31: Tlp Management Services Llc 4 | CA31: blendSAF
